{
  "success": false,
  "return_code": 2,
  "execution_time": 3.7715320587158203,
  "timestamp": "20250910_211957",
  "category": "unit",
  "stats": {
    "total": 0,
    "passed": 0,
    "failed": 0,
    "skipped": 0,
    "errors": 0,
    "warnings": 0
  },
  "coverage": null,
  "stdout": "\n==================================== ERRORS ====================================\n\u001b[31m\u001b[1m________________ ERROR collecting tests/test_enhanced_tools.py _________________\u001b[0m\n\u001b[31mvenv/lib/python3.13/site-packages/_pytest/python.py:498: in importtestmodule\n    mod = import_path(\nvenv/lib/python3.13/site-packages/_pytest/pathlib.py:587: in import_path\n    importlib.import_module(module_name)\n/opt/homebrew/Cellar/python@3.13/3.13.5/Frameworks/Python.framework/Versions/3.13/lib/python3.13/importlib/__init__.py:88: in import_module\n    return _bootstrap._gcd_import(name[level:], package, level)\n           ^^^^^^^^^^^^^^^^^^^^^^^^^^^^^^^^^^^^^^^^^^^^^^^^^^^^\n<frozen importlib._bootstrap>:1387: in _gcd_import\n    ???\n<frozen importlib._bootstrap>:1360: in _find_and_load\n    ???\n<frozen importlib._bootstrap>:1331: in _find_and_load_unlocked\n    ???\n<frozen importlib._bootstrap>:935: in _load_unlocked\n    ???\nvenv/lib/python3.13/site-packages/_pytest/assertion/rewrite.py:177: in exec_module\n    source_stat, co = _rewrite_test(fn, self.config)\n                      ^^^^^^^^^^^^^^^^^^^^^^^^^^^^^^\nvenv/lib/python3.13/site-packages/_pytest/assertion/rewrite.py:357: in _rewrite_test\n    tree = ast.parse(source, filename=strfn)\n           ^^^^^^^^^^^^^^^^^^^^^^^^^^^^^^^^^\n/opt/homebrew/Cellar/python@3.13/3.13.5/Frameworks/Python.framework/Versions/3.13/lib/python3.13/ast.py:50: in parse\n    return compile(source, filename, mode, flags,\nE     File \"/Users/ridam.chhapiya/Downloads/MyProd/competitor-research-agent/tests/test_enhanced_tools.py\", line 67\nE       def test_empty_query_handling(self):\nE       ^^^\nE   IndentationError: expected an indented block after function definition on line 65\u001b[0m\n\u001b[31m\u001b[1m__________________ ERROR collecting tests/test_integration.py __________________\u001b[0m\n'integration' not found in `markers` configuration option\n------------------------------- Captured stdout --------------------------------\n2025-09-10 21:20:00,343 - INFO - competitor_research_agent - Enhanced logging system initialized\n2025-09-10 21:20:00,624 - INFO - competitor_research_agent - Gemini API configured successfully\n\u001b[31m\u001b[1m_____________________ ERROR collecting tests/test_tools.py _____________________\u001b[0m\n'unit' not found in `markers` configuration option\n\u001b[31m\u001b[1m__________________ ERROR collecting tests/test_unit_basic.py ___________________\u001b[0m\n'unit' not found in `markers` configuration option\n\u001b[31m\u001b[1m___________________ ERROR collecting tests/test_workflow.py ____________________\u001b[0m\n'integration' not found in `markers` configuration option\n\u001b[33m=============================== warnings summary ===============================\u001b[0m\nsrc/utils/logger.py:43\nsrc/utils/logger.py:43\nsrc/utils/logger.py:43\nsrc/utils/logger.py:43\n  /Users/ridam.chhapiya/Downloads/MyProd/competitor-research-agent/src/utils/logger.py:43: DeprecationWarning: datetime.datetime.utcnow() is deprecated and scheduled for removal in a future version. Use timezone-aware objects to represent datetimes in UTC: datetime.datetime.now(datetime.UTC).\n    'timestamp': datetime.utcnow().isoformat(),\n\n-- Docs: https://docs.pytest.org/en/stable/how-to/capture-warnings.html\n- generated xml file: /Users/ridam.chhapiya/Downloads/MyProd/competitor-research-agent/test_reports/junit_20250910_211957.xml -\n- Generated html report: file:///Users/ridam.chhapiya/Downloads/MyProd/competitor-research-agent/test_reports/report_20250910_211957.html -\n\u001b[36m\u001b[1m=========================== short test summary info ============================\u001b[0m\n\u001b[31mERROR\u001b[0m tests/test_enhanced_tools.py\n\u001b[31mERROR\u001b[0m tests/test_integration.py - Failed: 'integration' not found in `markers` configuration option\n\u001b[31mERROR\u001b[0m tests/test_tools.py - Failed: 'unit' not found in `markers` configuration option\n\u001b[31mERROR\u001b[0m tests/test_unit_basic.py - Failed: 'unit' not found in `markers` configuration option\n\u001b[31mERROR\u001b[0m tests/test_workflow.py - Failed: 'integration' not found in `markers` configuration option\n!!!!!!!!!!!!!!!!!!! Interrupted: 5 errors during collection !!!!!!!!!!!!!!!!!!!!\n\u001b[31m\u001b[33m4 warnings\u001b[0m, \u001b[31m\u001b[1m5 errors\u001b[0m\u001b[31m in 2.70s\u001b[0m\u001b[0m\n",
  "stderr": "",
  "command": "python -m pytest -m unit -q --tb=short --strict-markers --color=yes --durations=10 --junitxml=test_reports/junit_20250910_211957.xml --html=test_reports/report_20250910_211957.html --self-contained-html"
}